Workbook

Sheet Negócios
A1: ANO | B1: MES | C1: ID_DO_CLIENTE | D1: CLIENTE | E1: ID_NEGOCIO | F1: CONTRATO | G1: ID_ITEM_DE_LINHA | H1: CATEGORIA_DO_ITEM | I1: BOOKING | J1: ARR | K1: RESTANTE_ARR | L1: MRR | M1: NMRR | N1: MRR_EXPANSAO | O1: MRR_RENOVACAO | P1: CONSULTOR | Q1: EQUIPE | R1: VERTICAL | S1: FECHAMENTO_NEGOCIO | T1: FECHAMENTO_AJUSTADO | U1: DATA_DE_INICIO | V1: DATA_DE_RENOVACAO | W1: VIGENCIA | X1: DURACAO | Y1: TIPO_DO_CONTRATO | Z1: TIPO_DA_VENDA | AA1: FORMA_DE_PAGAMENTO | AB1: PARCELAS | AC1: PIPELINE | AD1: ITEM_DE_LINHA | AE1: FAMILIA_DO_ITEM_DE_LINHA | AF1: APLICACAO_DO_ITEM_DE_LINHA | AG1: Acel Form Pag | AH1: Pago >400k
A2: 2026 | B2: 1 | C2: 19435599785 | D2: Prefeitura do Município de Cianorte | E2: 21648281648 | F2: 635639 | G2: 49516753480 | H2: Software | I2: 7432 | J2: 7432 | K2: 0 | L2: 619.33333 | M2: 0 | N2: 0 | O2: 0 | P2: deize.rudek@altoqi.com.br | Q2: B2G | R2: B2G | S2: 46041 | T2: 46041 | U2: 45982 | W2: 12 meses | X2: 12 | Y2: Vitalício | AA2: Transferência bancária | AB2: 1 | AC2: Comercial B2G | AD2: SSA 1 ano para AltoQi Builder Premium Governo | AE2: Builder | AF2: Premium | AG2: =IF(IFERROR(SEARCH("Recorrente",AA2),0)>0,"Recorrente",IF(AB2=1,"À Vista",IF(AB2<=3,"CC 3x",IF(AB2<=12,"CC 12x",IF(AB2>12,"Recorrente",""))))) -> À Vista | AH2: =IF(AND(SUMIF(E:E,E2,I:I)>=400000,Q2="B2G"),"n","")
A3: 2026 | B3: 1 | C3: 19435599785 | D3: Prefeitura do Município de Cianorte | E3: 21648281648 | F3: 635639 | G3: 49516753481 | H3: Software | I3: 10695 | J3: 10695 | K3: 0 | L3: 891.25 | M3: 0 | N3: 0 | O3: 0 | P3: deize.rudek@altoqi.com.br | Q3: B2G | R3: B2G | S3: 46041 | T3: 46041 | U3: 45982 | W3: 12 meses | X3: 12 | Y3: Vitalício | AA3: Transferência bancária | AB3: 1 | AC3: Comercial B2G | AD3: SSA 1 ano para AltoQi Eberick Infinity Governo | AE3: Eberick | AF3: Infinity | AG3: =IF(IFERROR(SEARCH("Recorrente",AA3),0)>0,"Recorrente",IF(AB3=1,"À Vista",IF(AB3<=3,"CC 3x",IF(AB3<=12,"CC 12x",IF(AB3>12,"Recorrente",""))))) -> À Vista | AH3: =IF(AND(SUMIF(E:E,E3,I:I)>=400000,Q3="B2G"),"n","")
A4: 2026 | B4: 1 | C4: 19435599785 | D4: Prefeitura do Município de Cianorte | E4: 21648281648 | F4: 635639 | G4: 49516753482 | H4: Software | I4: 5799 | J4: 5799 | K4: 0 | L4: 483.25 | M4: 0 | N4: 0 | O4: 0 | P4: deize.rudek@altoqi.com.br | Q4: B2G | R4: B2G | S4: 46041 | T4: 46041 | U4: 45982 | W4: 12 meses | X4: 12 | Y4: Vitalício | AA4: Transferência bancária | AB4: 1 | AC4: Comercial B2G | AD4: SSA 1 ano para AltoQi Builder Infinity Governo | AE4: Builder | AF4: Infinity | AG4: =IF(IFERROR(SEARCH("Recorrente",AA4),0)>0,"Recorrente",IF(AB4=1,"À Vista",IF(AB4<=3,"CC 3x",IF(AB4<=12,"CC 12x",IF(AB4>12,"Recorrente",""))))) -> À Vista | AH4: =IF(AND(SUMIF(E:E,E4,I:I)>=400000,Q4="B2G"),"n","")
A5: 2026 | B5: 1 | C5: 19435599785 | D5: Prefeitura do Município de Cianorte | E5: 21817048369 | F5: 635661 | G5: 49669089590 | H5: Software | I5: 15980.16 | J5: 15980.16 | K5: 0 | L5: 1331.68 | M5: 1331.68 | N5: 0 | O5: 0 | P5: deize.rudek@altoqi.com.br | Q5: B2G | R5: B2G | S5: 46043 | T5: 46043 | V5: 46408 | W5: 12 meses | X5: 12 | Y5: Assinatura | AA5: Transferência bancária | AB5: 1 | AC5: Comercial B2G | AD5: Plano Visus Obras Públicas Premium Governo | AE5: Visus Obras Públicas | AF5: Premium | AG5: =IF(IFERROR(SEARCH("Recorrente",AA5),0)>0,"Recorrente",IF(AB5=1,"À Vista",IF(AB5<=3,"CC 3x",IF(AB5<=12,"CC 12x",IF(AB5>12,"Recorrente",""))))) -> À Vista | AH5: =IF(AND(SUMIF(E:E,E5,I:I)>=400000,Q5="B2G"),"n","")
A6: 2026 | B6: 1 | C6: 19435640354 | D6: FUNDACAO UNIVERSIDADE FEDERAL DA GRANDE DOURADOS | E6: 29857451798 | F6: 635750 | G6: 49949823822 | H6: Software | I6: 13932 | J6: 13932 | K6: 0 | L6: 1161 | M6: 1161 | N6: 0 | O6: 0 | P6: deize.rudek@altoqi.com.br | Q6: B2G | R6: B2G | S6: 46049 | T6: 46049 | V6: 46414 | W6: 12 meses | X6: 12 | Y6: Assinatura | AA6: Transferência bancária | AB6: 1 | AC6: Comercial B2G | AD6: Plano AltoQi Builder Premium Governo | AE6: Builder | AF6: Premium | AG6: =IF(IFERROR(SEARCH("Recorrente",AA6),0)>0,"Recorrente",IF(AB6=1,"À Vista",IF(AB6<=3,"CC 3x",IF(AB6<=12,"CC 12x",IF(AB6>12,"Recorrente",""))))) -> À Vista | AH6: =IF(AND(SUMIF(E:E,E6,I:I)>=400000,Q6="B2G"),"n","")
A7: 2026 | B7: 1 | C7: 19435640354 | D7: FUNDACAO UNIVERSIDADE FEDERAL DA GRANDE DOURADOS | E7: 29857451798 | F7: 635750 | G7: 49949823823 | H7: Software | I7: 5436 | J7: 5436 | K7: 0 | L7: 453 | M7: 453 | N7: 0 | O7: 0 | P7: deize.rudek@altoqi.com.br | Q7: B2G | R7: B2G | S7: 46049 | T7: 46049 | V7: 46414 | W7: 12 meses | X7: 12 | Y7: Assinatura | AA7: Transferência bancária | AB7: 1 | AC7: Comercial B2G | AD7: Plano AltoQi Eberick Premium Governo | AE7: Eberick | AF7: Premium | AG7: =IF(IFERROR(SEARCH("Recorrente",AA7),0)>0,"Recorrente",IF(AB7=1,"À Vista",IF(AB7<=3,"CC 3x",IF(AB7<=12,"CC 12x",IF(AB7>12,"Recorrente",""))))) -> À Vista | AH7: =IF(AND(SUMIF(E:E,E7,I:I)>=400000,Q7="B2G"),"n","")
A8: 2026 | B8: 1 | C8: 19435564728 | D8: Prefeitura Municipal de Imbe | E8: 29861060658 | F8: 635812 | G8: 50425912479 | H8: Software | I8: 105560.16 | J8: 52780.08 | K8: 52780.08 | L8: 4398.34 | M8: 4398.34 | N8: 0 | O8: 0 | P8: deize.rudek@altoqi.com.br | Q8: B2G | R8: B2G | S8: 46052 | T8: 46052 | V8: 46782 | W8: 24 meses | X8: 24 | Y8: Assinatura | AA8: Transferência bancária | AB8: 1 | AC8: Comercial B2G | AD8: Plataforma BIM - AltoQi Gestão Pública – Projetos, Gestão e Controle de Custos | AE8: Visus Control Tower | AF8: Sem Aplicação | AG8: =IF(IFERROR(SEARCH("Recorrente",AA8),0)>0,"Recorrente",IF(AB8=1,"À Vista",IF(AB8<=3,"CC 3x",IF(AB8<=12,"CC 12x",IF(AB8>12,"Recorrente",""))))) -> À Vista | AH8: =IF(AND(SUMIF(E:E,E8,I:I)>=400000,Q8="B2G"),"n","")
A9: 2026 | B9: 1 | C9: 19540695847 | D9: MUNICIPIO DE REALEZA | E9: 30153859675 | F9: 635747 | G9: 49949879727 | H9: Software | I9: 7432 | J9: 3716 | K9: 3716 | L9: 309.66667 | M9: 0 | N9: 0 | O9: 0 | P9: deize.rudek@altoqi.com.br | Q9: B2G | R9: B2G | S9: 46049 | T9: 46049 | W9: 24 meses | X9: 24 | Y9: Vitalício | AA9: Transferência bancária | AB9: 1 | AC9: Comercial B2G | AD9: SSA 2 anos para AltoQi Builder Premium Governo | AE9: Builder | AF9: Premium | AG9: =IF(IFERROR(SEARCH("Recorrente",AA9),0)>0,"Recorrente",IF(AB9=1,"À Vista",IF(AB9<=3,"CC 3x",IF(AB9<=12,"CC 12x",IF(AB9>12,"Recorrente",""))))) -> À Vista | AH9: =IF(AND(SUMIF(E:E,E9,I:I)>=400000,Q9="B2G"),"n","")
A10: 2026 | B10: 1 | C10: 19540695847 | D10: MUNICIPIO DE REALEZA | E10: 30153859675 | F10: 635747 | G10: 49949879728 | H10: Software | I10: 18576 | J10: 0 | K10: 0 | L10: 0 | M10: 0 | N10: 0 | O10: 0 | P10: deize.rudek@altoqi.com.br | Q10: B2G | R10: B2G | S10: 46049 | T10: 46049 | W10: Vitalício | Y10: Vitalício | AA10: Transferência bancária | AB10: 1 | AC10: Comercial B2G | AD10: Plano Builder 2025 Premium Governo | AE10: Builder | AF10: Premium | AG10: =IF(IFERROR(SEARCH("Recorrente",AA10),0)>0,"Recorrente",IF(AB10=1,"À Vista",IF(AB10<=3,"CC 3x",IF(AB10<=12,"CC 12x",IF(AB10>12,"Recorrente",""))))) -> À Vista | AH10: =IF(AND(SUMIF(E:E,E10,I:I)>=400000,Q10="B2G"),"n","")
A11: 2026 | B11: 1 | C11: 19540695847 | D11: MUNICIPIO DE REALEZA | E11: 30153859675 | F11: 635747 | G11: 49949879729 | H11: Software | I11: 21744 | J11: 0 | K11: 0 | L11: 0 | M11: 0 | N11: 0 | O11: 0 | P11: deize.rudek@altoqi.com.br | Q11: B2G | R11: B2G | S11: 46049 | T11: 46049 | W11: Vitalício | Y11: Vitalício | AA11: Transferência bancária | AB11: 1 | AC11: Comercial B2G | AD11: Plano Eberick 2025 Premium Governo | AE11: Eberick | AF11: Premium | AG11: =IF(IFERROR(SEARCH("Recorrente",AA11),0)>0,"Recorrente",IF(AB11=1,"À Vista",IF(AB11<=3,"CC 3x",IF(AB11<=12,"CC 12x",IF(AB11>12,"Recorrente",""))))) -> À Vista | AH11: =IF(AND(SUMIF(E:E,E11,I:I)>=400000,Q11="B2G"),"n","")
A12: 2026 | B12: 1 | C12: 19540695847 | D12: MUNICIPIO DE REALEZA | E12: 30153859675 | F12: 635747 | G12: 49949879730 | H12: Software | I12: 8698 | J12: 4349 | K12: 4349 | L12: 362.41667 | M12: 0 | N12: 0 | O12: 0 | P12: deize.rudek@altoqi.com.br | Q12: B2G | R12: B2G | S12: 46049 | T12: 46049 | W12: 24 meses | X12: 24 | Y12: Vitalício | AA12: Transferência bancária | AB12: 1 | AC12: Comercial B2G | AD12: SSA 2 anos para AltoQi Eberick Premium Governo | AE12: Eberick | AF12: Premium | AG12: =IF(IFERROR(SEARCH("Recorrente",AA12),0)>0,"Recorrente",IF(AB12=1,"À Vista",IF(AB12<=3,"CC 3x",IF(AB12<=12,"CC 12x",IF(AB12>12,"Recorrente",""))))) -> À Vista | AH12: =IF(AND(SUMIF(E:E,E12,I:I)>=400000,Q12="B2G"),"n","")
A13: 2026 | B13: 1 | C13: 30176499367 | D13: UNIVERSIDADE FEDERAL DE UBERLANDIA | E13: 33917004397 | F13: 635688 | G13: 49708158237 | H13: Software | I13: 57984 | J13: 0 | K13: 0 | L13: 0 | M13: 0 | N13: 0 | O13: 0 | P13: soraia@altoqi.com.br | Q13: B2G | R13: B2G | S13: 46044 | T13: 46044 | W13: Vitalício | Y13: Vitalício | AA13: Transferência bancária | AB13: 1 | AC13: Comercial B2G | AD13: Plano AltoQi Builder 2025 Infinity Governo - Upgrade | AE13: Builder | AF13: Infinity | AG13: =IF(IFERROR(SEARCH("Recorrente",AA13),0)>0,"Recorrente",IF(AB13=1,"À Vista",IF(AB13<=3,"CC 3x",IF(AB13<=12,"CC 12x",IF(AB13>12,"Recorrente",""))))) -> À Vista | AH13: =IF(AND(SUMIF(E:E,E13,I:I)>=400000,Q13="B2G"),"n","")
A14: 2026 | B14: 1 | C14: 35907319569 | D14: ORGANIZACAO BRASILEIRA PARA O DESENVOLVIMENTO CIENTIFICO E TECNOLOGICO DO CONTROLE DO ESPACO AEREO-CTCEA | E14: 38789220430 | F14: 635786 | G14: 50274464379 | H14: Software | I14: 21744 | J14: 21744 | K14: 0 | L14: 1812 | M14: 0 | N14: 1812 | O14: 0 | P14: jordayn.almeida@altoqi.com.br | Q14: B2G | R14: B2G | S14: 46051 | T14: 46051 | U14: 46000 | V14: 46416 | W14: 12 meses | X14: 12 | Y14: Assinatura | AA14: Transferência bancária | AB14: 1 | AC14: Comercial B2G | AD14: Plano AltoQi Builder Infinity Governo | AE14: Builder | AF14: Infinity | AG14: =IF(IFERROR(SEARCH("Recorrente",AA14),0)>0,"Recorrente",IF(AB14=1,"À Vista",IF(AB14<=3,"CC 3x",IF(AB14<=12,"CC 12x",IF(AB14>12,"Recorrente",""))))) -> À Vista | AH14: =IF(AND(SUMIF(E:E,E14,I:I)>=400000,Q14="B2G"),"n","")
A15: 2026 | B15: 1 | C15: 35907319569 | D15: ORGANIZACAO BRASILEIRA PARA O DESENVOLVIMENTO CIENTIFICO E TECNOLOGICO DO CONTROLE DO ESPACO AEREO-CTCEA | E15: 38789220430 | F15: 635786 | G15: 50274464379 | H15: Software | I15: 21744 | J15: 21744 | K15: 0 | L15: 1812 | M15: 0 | N15: 1812 | O15: 0 | P15: soraia@altoqi.com.br | Q15: B2G | R15: B2G | S15: 46051 | T15: 46051 | U15: 46000 | V15: 46416 | W15: 12 meses | X15: 12 | Y15: Assinatura | AA15: Transferência bancária | AB15: 1 | AC15: Comercial B2G | AD15: Plano AltoQi Builder Infinity Governo | AE15: Builder | AF15: Infinity | AG15: =IF(IFERROR(SEARCH("Recorrente",AA15),0)>0,"Recorrente",IF(AB15=1,"À Vista",IF(AB15<=3,"CC 3x",IF(AB15<=12,"CC 12x",IF(AB15>12,"Recorrente",""))))) -> À Vista | AH15: =IF(AND(SUMIF(E:E,E15,I:I)>=400000,Q15="B2G"),"n","")
A16: 2026 | B16: 1 | C16: 19485596080 | D16: MUNICÍPIO DE FOZ DO IGUAÇU | E16: 39962115145 | F16: 635520 | G16: 48560859043 | H16: Software | I16: 15990 | J16: 15990 | K16: 0 | L16: 1332.5 | M16: 1332.5 | N16: 0 | O16: 0 | P16: henry.petersen@altoqi.com.br | Q16: B2G | R16: B2G | S16: 46030 | T16: 46030 | V16: 46395 | W16: 12 meses | X16: 12 | Y16: Assinatura | AA16: Transferência bancária | AB16: 1 | AC16: Comercial B2G | AD16: Plano Visus Obras Públicas Infinity Governo | AE16: Visus Obras Públicas | AF16: Infinity | AG16: =IF(IFERROR(SEARCH("Recorrente",AA16),0)>0,"Recorrente",IF(AB16=1,"À Vista",IF(AB16<=3,"CC 3x",IF(AB16<=12,"CC 12x",IF(AB16>12,"Recorrente",""))))) -> À Vista | AH16: =IF(AND(SUMIF(E:E,E16,I:I)>=400000,Q16="B2G"),"n","")
A17: 2026 | B17: 1 | C17: 19435497254 | D17: FUNDACAO CULTURAL E DE FOMENTO A PESQUISA, ENSINO, EXTENSAO E INOVACAO - FADEX | E17: 40516172212 | F17: 625579 | G17: 49068412739 | H17: Software | I17: 5436 | J17: 5436 | K17: 0 | L17: 453 | M17: 0 | N17: 46 | O17: 407 | P17: tabata.couto@altoqi.com.br | Q17: B2G | R17: B2G | S17: 46036 | T17: 46036 | U17: 46038 | V17: 46403 | W17: 12 meses | X17: 12 | Y17: Assinatura | Z17: Renovação com Expansão | AA17: Transferência bancária | AB17: 1 | AC17: Comercial B2G | AD17: Plano AltoQi Eberick Premium Governo | AE17: Eberick | AF17: Premium | AG17: =IF(IFERROR(SEARCH("Recorrente",AA17),0)>0,"Recorrente",IF(AB17=1,"À Vista",IF(AB17<=3,"CC 3x",IF(AB17<=12,"CC 12x",IF(AB17>12,"Recorrente",""))))) -> À Vista | AH17: =IF(AND(SUMIF(E:E,E17,I:I)>=400000,Q17="B2G"),"n","")
A18: 2026 | B18: 1 | C18: 29124531791 | D18: ASSOCIACAO PAULISTA SUDOESTE DA IASD | E18: 41109232824 | F18: 625944 | G18: 48886123146 | H18: Software | I18: 5394 | J18: 5394 | K18: 0 | L18: 449.5 | M18: 0 | N18: 55.5 | O18: 394 | P18: jenifer.soares@altoqi.com.br | Q18: IES | R18: B2E | S18: 46035 | T18: 46035 | U18: 46050 | V18: 46415 | W18: 12 meses | X18: 12 | Y18: Assinatura | Z18: Renovação | AA18: Boleto | AB18: 1 | AC18: Comercial B2E - Instituição | AD18: Plano Builder Premium | AE18: Builder | AF18: Premium | AG18: =IF(IFERROR(SEARCH("Recorrente",AA18),0)>0,"Recorrente",IF(AB18=1,"À Vista",IF(AB18<=3,"CC 3x",IF(AB18<=12,"CC 12x",IF(AB18>12,"Recorrente",""))))) -> À Vista | AH18: =IF(AND(SUMIF(E:E,E18,I:I)>=400000,Q18="B2G"),"n","")
A19: 2026 | B19: 1 | C19: 29124531791 | D19: ASSOCIACAO PAULISTA SUDOESTE DA IASD | E19: 41109232824 | F19: 625944 | G19: 48886123147 | H19: Software | I19: 5394 | J19: 5394 | K19: 0 | L19: 449.5 | M19: 0 | N19: 55.5 | O19: 394 | P19: jenifer.soares@altoqi.com.br | Q19: IES | R19: B2E | S19: 46035 | T19: 46035 | U19: 46050 | V19: 46415 | W19: 12 meses | X19: 12 | Y19: Assinatura | Z19: Renovação | AA19: Boleto | AB19: 1 | AC19: Comercial B2E - Instituição | AD19: Plano Eberick Premium | AE19: Eberick | AF19: Premium | AG19: =IF(IFERROR(SEARCH("Recorrente",AA19),0)>0,"Recorrente",IF(AB19=1,"À Vista",IF(AB19<=3,"CC 3x",IF(AB19<=12,"CC 12x",IF(AB19>12,"Recorrente",""))))) -> À Vista | AH19: =IF(AND(SUMIF(E:E,E19,I:I)>=400000,Q19="B2G"),"n","")
A20: 2026 | B20: 1 | C20: 20534852467 | D20: MUNICIPIO DE EMBU DAS ARTES | E20: 41206575190 | F20: 625980 | G20: 50350997306 | H20: Software | I20: 4007.16 | J20: 4007.16 | K20: 0 | L20: 333.93 | M20: 0 | N20: 14.93 | O20: 319 | P20: angelica.steinbach@altoqi.com.br | Q20: B2G | R20: B2G | S20: 46051 | T20: 46051 | U20: 46051 | V20: 46416 | W20: 12 meses | X20: 12 | Y20: Assinatura | Z20: Renovação | AA20: Transferência bancária | AB20: 1 | AC20: Comercial B2G | AD20: Plano AltoQi Builder Premium Governo | AE20: Builder | AF20: Premium | AG20: =IF(IFERROR(SEARCH("Recorrente",AA20),0)>0,"Recorrente",IF(AB20=1,"À Vista",IF(AB20<=3,"CC 3x",IF(AB20<=12,"CC 12x",IF(AB20>12,"Recorrente",""))))) -> À Vista | AH20: =IF(AND(SUMIF(E:E,E20,I:I)>=400000,Q20="B2G"),"n","")
A21: 2026 | B21: 1 | C21: 19435452707 | D21: MUNICIPIO DE URUOCA | E21: 41255385229 | F21: 635553 | G21: 48885894405 | H21: Software | I21: 4644 | J21: 4644 | K21: 0 | L21: 387 | M21: 0 | N21: 52.52 | O21: 334.47857 | P21: deize.rudek@altoqi.com.br | Q21: B2G | R21: B2G | S21: 46035 | T21: 46035 | U21: 46052 | V21: 46400 | W21: 12 meses | X21: 12 | Y21: Assinatura | AA21: Transferência bancária | AB21: 1 | AC21: Comercial B2G | AD21: Plano AltoQi Builder Premium Governo | AE21: Builder | AF21: Premium | AG21: =IF(IFERROR(SEARCH("Recorrente",AA21),0)>0,"Recorrente",IF(AB21=1,"À Vista",IF(AB21<=3,"CC 3x",IF(AB21<=12,"CC 12x",IF(AB21>12,"Recorrente",""))))) -> À Vista | AH21: =IF(AND(SUMIF(E:E,E21,I:I)>=400000,Q21="B2G"),"n","")
A22: 2026 | B22: 1 | C22: 19435452707 | D22: MUNICIPIO DE URUOCA | E22: 41255385229 | F22: 635553 | G22: 48885894406 | H22: Software | I22: 5436 | J22: 5436 | K22: 0 | L22: 453 | M22: 0 | N22: 61.48 | O22: 391.52143 | P22: deize.rudek@altoqi.com.br | Q22: B2G | R22: B2G | S22: 46035 | T22: 46035 | U22: 46052 | V22: 46400 | W22: 12 meses | X22: 12 | Y22: Assinatura | AA22: Transferência bancária | AB22: 1 | AC22: Comercial B2G | AD22: Plano AltoQi Eberick Premium Governo | AE22: Eberick | AF22: Premium | AG22: =IF(IFERROR(SEARCH("Recorrente",AA22),0)>0,"Recorrente",IF(AB22=1,"À Vista",IF(AB22<=3,"CC 3x",IF(AB22<=12,"CC 12x",IF(AB22>12,"Recorrente",""))))) -> À Vista | AH22: =IF(AND(SUMIF(E:E,E22,I:I)>=400000,Q22="B2G"),"n","")
A23: 2026 | B23: 1 | C23: 19435709240 | D23: VICTA PARTICIPACOES LTDA | E23: 41513028145 | F23: 635488 | G23: 48457676122 | H23: Software | I23: 8394 | J23: 8394 | K23: 0 | L23: 699.5 | M23: 699.5 | N23: 0 | O23: 0 | P23: henrique.silva@altoqi.com.br | Q23: B2B Construtora | R23: B2B Construtora | S23: 46028 | T23: 46028 | V23: 46393 | W23: 12 meses | X23: 12 | Y23: Assinatura | AA23: Boleto Recorrente | AB23: 12 | AC23: Comercial B2B - Construtoras | AD23: Plano Visus Cost Management Enterprise | AE23: Visus Cost | AF23: Enterprise | AG23: =IF(IFERROR(SEARCH("Recorrente",AA23),0)>0,"Recorrente",IF(AB23=1,"À Vista",IF(AB23<=3,"CC 3x",IF(AB23<=12,"CC 12x",IF(AB23>12,"Recorrente",""))))) -> Recorrente | AH23: =IF(AND(SUMIF(E:E,E23,I:I)>=400000,Q23="B2G"),"n","")
A24: 2026 | B24: 1 | C24: 19435393801 | D24: UNIVERSIDADE TECNOLOGICA FEDERAL DO PARANA | E24: 43288784965 | F24: 635824 | G24: 50425093796 | H24: Software | I24: 23220 | J24: 23220 | K24: 0 | L24: 1935 | M24: 1935 | N24: 0 | O24: 0 | P24: fernanda.barbosa@altoqi.com.br | Q24: B2G | R24: B2G | S24: 46052 | T24: 46052 | V24: 46417 | W24: 12 meses | X24: 12 | Y24: Assinatura | AA24: Transferência bancária | AB24: 1 | AC24: Comercial B2G | AD24: Plano AltoQi Builder Premium Governo | AE24: Builder | AF24: Premium | AG24: =IF(IFERROR(SEARCH("Recorrente",AA24),0)>0,"Recorrente",IF(AB24=1,"À Vista",IF(AB24<=3,"CC 3x",IF(AB24<=12,"CC 12x",IF(AB24>12,"Recorrente",""))))) -> À Vista | AH24: =IF(AND(SUMIF(E:E,E24,I:I)>=400000,Q24="B2G"),"n","")
A25: 2026 | B25: 1 | C25: 19435393801 | D25: UNIVERSIDADE TECNOLOGICA FEDERAL DO PARANA | E25: 43288784965 | F25: 635824 | G25: 50425093798 | H25: Software | I25: 7990.08 | J25: 7990.08 | K25: 0 | L25: 665.84 | M25: 665.84 | N25: 0 | O25: 0 | P25: fernanda.barbosa@altoqi.com.br | Q25: B2G | R25: B2G | S25: 46052 | T25: 46052 | V25: 46417 | W25: 12 meses | X25: 12 | Y25: Assinatura | AA25: Transferência bancária | AB25: 1 | AC25: Comercial B2G | AD25: Plano Visus Obras Públicas Premium Governo | AE25: Visus Obras Públicas | AF25: Premium | AG25: =IF(IFERROR(SEARCH("Recorrente",AA25),0)>0,"Recorrente",IF(AB25=1,"À Vista",IF(AB25<=3,"CC 3x",IF(AB25<=12,"CC 12x",IF(AB25>12,"Recorrente",""))))) -> À Vista | AH25: =IF(AND(SUMIF(E:E,E25,I:I)>=400000,Q25="B2G"),"n","")
A26: 2026 | B26: 1 | C26: 19435393801 | D26: UNIVERSIDADE TECNOLOGICA FEDERAL DO PARANA | E26: 43288784965 | F26: 635824 | G26: 50425093799 | H26: Software | I26: 5436 | J26: 5436 | K26: 0 | L26: 453 | M26: 453 | N26: 0 | O26: 0 | P26: fernanda.barbosa@altoqi.com.br | Q26: B2G | R26: B2G | S26: 46052 | T26: 46052 | V26: 46417 | W26: 12 meses | X26: 12 | Y26: Assinatura | AA26: Transferência bancária | AB26: 1 | AC26: Comercial B2G | AD26: Plano AltoQi Eberick Premium Governo | AE26: Eberick | AF26: Premium | AG26: =IF(IFERROR(SEARCH("Recorrente",AA26),0)>0,"Recorrente",IF(AB26=1,"À Vista",IF(AB26<=3,"CC 3x",IF(AB26<=12,"CC 12x",IF(AB26>12,"Recorrente",""))))) -> À Vista | AH26: =IF(AND(SUMIF(E:E,E26,I:I)>=400000,Q26="B2G"),"n","")
A27: 2026 | B27: 1 | C27: 19435497254 | D27: FUNDACAO CULTURAL E DE FOMENTO A PESQUISA, ENSINO, EXTENSAO E INOVACAO - FADEX | E27: 44063859254 | F27: 627642 | G27: 49007574180 | H27: Software | I27: 14496 | J27: 14496 | K27: 0 | L27: 1208 | M27: 1208 | N27: 0 | O27: 0 | P27: tabata.couto@altoqi.com.br | Q27: B2G | R27: B2G | S27: 46037 | T27: 46037 | V27: 46467 | W27: 12 meses | X27: 14 | Y27: Assinatura | Z27: Renovação | AA27: Transferência bancária | AB27: 1 | AC27: Comercial B2G | AD27: Plano AltoQi Builder Infinity Governo | AE27: Builder | AF27: Infinity | AG27: =IF(IFERROR(SEARCH("Recorrente",AA27),0)>0,"Recorrente",IF(AB27=1,"À Vista",IF(AB27<=3,"CC 3x",IF(AB27<=12,"CC 12x",IF(AB27>12,"Recorrente",""))))) -> À Vista | AH27: =IF(AND(SUMIF(E:E,E27,I:I)>=400000,Q27="B2G"),"n","")
A28: 2026 | B28: 1 | C28: 29287902612 | D28: UNESPAR - UNIVERSIDADE ESTADUAL DO PARANA | E28: 44506492043 | F28: 635514 | G28: 48545432894 | H28: Software | I28: 13368 | J28: 13368 | K28: 0 | L28: 1114 | M28: 1114 | N28: 0 | O28: 0 | P28: fernanda.barbosa@altoqi.com.br | Q28: B2G | R28: B2G | S28: 46030 | T28: 46030 | V28: 46395 | W28: 12 meses | X28: 12 | Y28: Assinatura | AA28: Transferência bancária | AB28: 1 | AC28: Comercial B2G | AD28: Plano AltoQi Eberick Infinity Governo | AE28: Eberick | AF28: Infinity | AG28: =IF(IFERROR(SEARCH("Recorrente",AA28),0)>0,"Recorrente",IF(AB28=1,"À Vista",IF(AB28<=3,"CC 3x",IF(AB28<=12,"CC 12x",IF(AB28>12,"Recorrente",""))))) -> À Vista | AH28: =IF(AND(SUMIF(E:E,E28,I:I)>=400000,Q28="B2G"),"n","")
A29: 2026 | B29: 1 | C29: 19435447599 | D29: Prefeitura Municipal de Amambai-ms | E29: 45877912418 | F29: 635818 | G29: 50350906931 | H29: Software | I29: 32616 | J29: 10872 | K29: 21744 | L29: 906 | M29: 906 | N29: 0 | O29: 0 | P29: deize.rudek@altoqi.com.br | Q29: B2G | R29: B2G | S29: 46052 | T29: 46052 | V29: 47148 | W29: 36 meses | X29: 36 | Y29: Assinatura | AA29: Transferência bancária | AB29: 1 | AC29: Comercial B2G | AD29: Plano AltoQi Eberick Premium Governo | AE29: Eberick | AF29: Premium | AG29: =IF(IFERROR(SEARCH("Recorrente",AA29),0)>0,"Recorrente",IF(AB29=1,"À Vista",IF(AB29<=3,"CC 3x",IF(AB29<=12,"CC 12x",IF(AB29>12,"Recorrente",""))))) -> À Vista | AH29: =IF(AND(SUMIF(E:E,E29,I:I)>=400000,Q29="B2G"),"n","")
A30: 2026 | B30: 1 | C30: 19435447599 | D30: Prefeitura Municipal de Amambai-ms | E30: 45877912418 | F30: 635818 | G30: 50350906932 | H30: Software | I30: 27864 | J30: 9288 | K30: 18576 | L30: 774 | M30: 774 | N30: 0 | O30: 0 | P30: deize.rudek@altoqi.com.br | Q30: B2G | R30: B2G | S30: 46052 | T30: 46052 | V30: 47148 | W30: 36 meses | X30: 36 | Y30: Assinatura | AA30: Transferência bancária | AB30: 1 | AC30: Comercial B2G | AD30: Plano AltoQi Builder Premium Governo | AE30: Builder | AF30: Premium | AG30: =IF(IFERROR(SEARCH("Recorrente",AA30),0)>0,"Recorrente",IF(AB30=1,"À Vista",IF(AB30<=3,"CC 3x",IF(AB30<=12,"CC 12x",IF(AB30>12,"Recorrente",""))))) -> À Vista | AH30: =IF(AND(SUMIF(E:E,E30,I:I)>=400000,Q30="B2G"),"n","")
A31: 2026 | B31: 1 | C31: 19435567269 | D31: MUNICIPIO DE SAO BENTO DO SUL | E31: 46511646114 | F31: 635662 | G31: 49670317965 | H31: Curso | I31: 718.8 | J31: 718.8 | K31: 0 | L31: 59.9 | M31: 59.9 | N31: 0 | O31: 0 | P31: fernanda.barbosa@altoqi.com.br | Q31: B2G | R31: B2G | S31: 46043 | T31: 46043 | V31: 46408 | W31: 12 meses | X31: 12 | Y31: Curso | AA31: Transferência bancária | AB31: 1 | AC31: Comercial B2G | AD31: Plataforma AltoQi Education - Cursos de Software | AE31: Outros | AF31: Sem Aplicação | AG31: =IF(IFERROR(SEARCH("Recorrente",AA31),0)>0,"Recorrente",IF(AB31=1,"À Vista",IF(AB31<=3,"CC 3x",IF(AB31<=12,"CC 12x",IF(AB31>12,"Recorrente",""))))) -> À Vista | AH31: =IF(AND(SUMIF(E:E,E31,I:I)>=400000,Q31="B2G"),"n","")
A32: 2026 | B32: 1 | C32: 42179585166 | D32: MINISTERIO PUBLICO DO ESTADO DO ESPIRITO SANTO | E32: 46554281576 | F32: 635666 | G32: 49608453559 | H32: Software | I32: 10872 | J32: 5436 | K32: 5436 | L32: 453 | M32: 453 | N32: 0 | O32: 0 | P32: angelica.steinbach@altoqi.com.br | Q32: B2G | R32: B2G | S32: 46043 | T32: 46043 | V32: 46773 | W32: 24 meses | X32: 24 | Y32: Assinatura | AA32: Transferência bancária | AB32: 1 | AC32: Comercial B2G | AD32: Plano AltoQi Eberick Premium Governo | AE32: Eberick | AF32: Premium | AG32: =IF(IFERROR(SEARCH("Recorrente",AA32),0)>0,"Recorrente",IF(AB32=1,"À Vista",IF(AB32<=3,"CC 3x",IF(AB32<=12,"CC 12x",IF(AB32>12,"Recorrente",""))))) -> À Vista | AH32: =IF(AND(SUMIF(E:E,E32,I:I)>=400000,Q32="B2G"),"n","")
A33: 2026 | B33: 1 | C33: 42179585166 | D33: MINISTERIO PUBLICO DO ESTADO DO ESPIRITO SANTO | E33: 46554281576 | F33: 635666 | G33: 49608453560 | H33: Software | I33: 9288 | J33: 4644 | K33: 4644 | L33: 387 | M33: 387 | N33: 0 | O33: 0 | P33: angelica.steinbach@altoqi.com.br | Q33: B2G | R33: B2G | S33: 46043 | T33: 46043 | V33: 46773 | W33: 24 meses | X33: 24 | Y33: Assinatura | AA33: Transferência bancária | AB33: 1 | AC33: Comercial B2G | AD33: Plano AltoQi Builder Premium Governo | AE33: Builder | AF33: Premium | AG33: =IF(IFERROR(SEARCH("Recorrente",AA33),0)>0,"Recorrente",IF(AB33=1,"À Vista",IF(AB33<=3,"CC 3x",IF(AB33<=12,"CC 12x",IF(AB33>12,"Recorrente",""))))) -> À Vista | AH33: =IF(AND(SUMIF(E:E,E33,I:I)>=400000,Q33="B2G"),"n","")
A34: 2026 | B34: 1 | C34: 20535617041 | D34: MUNICIPIO DE ITAPECERICA DA SERRA | E34: 46559124409 | F34: 635778 | G34: 50273452422 | H34: Software | I34: 16308 | J34: 5436 | K34: 10872 | L34: 453 | M34: 453 | N34: 0 | O34: 0 | P34: deize.rudek@altoqi.com.br | Q34: B2G | R34: B2G | S34: 46050 | T34: 46050 | V34: 47146 | W34: 36 meses | X34: 36 | Y34: Assinatura | AA34: Transferência bancária | AB34: 1 | AC34: Comercial B2G | AD34: Plano AltoQi Eberick Premium Governo | AE34: Eberick | AF34: Premium | AG34: =IF(IFERROR(SEARCH("Recorrente",AA34),0)>0,"Recorrente",IF(AB34=1,"À Vista",IF(AB34<=3,"CC 3x",IF(AB34<=12,"CC 12x",IF(AB34>12,"Recorrente",""))))) -> À Vista | AH34: =IF(AND(SUMIF(E:E,E34,I:I)>=400000,Q34="B2G"),"n","")
A35: 2026 | B35: 1 | C35: 26512022954 | D35: RIBEIRO DO VALE ENGENHARIA LTDA | E35: 46588609583 | F35: 624533 | G35: 44801325474 | H35: Software | I35: 3299.88 | J35: 3299.88 | K35: 0 | L35: 274.99 | M35: 0 | N35: 25.16 | O35: 249.84 | P35: rubia.estipe@altoqi.com.br | Q35: Saving | R35: Saving | S35: 45979 | T35: 46023 | U35: 45994 | V35: 46359 | W35: 12 meses | X35: 12 | Y35: Assinatura | Z35: Renovação | AA35: Cartão de crédito | AB35: 12 | AC35: CS - Saving | AD35: Plano Builder Hidro Premium | AE35: Builder | AF35: Premium | AG35: =IF(IFERROR(SEARCH("Recorrente",AA35),0)>0,"Recorrente",IF(AB35=1,"À Vista",IF(AB35<=3,"CC 3x",IF(AB35<=12,"CC 12x",IF(AB35>12,"Recorrente",""))))) -> CC 12x | AH35: =IF(AND(SUMIF(E:E,E35,I:I)>=400000,Q35="B2G"),"n","")
A36: 2026 | B36: 1 | C36: 2075043 | D36: IGOR GUIMARAES MATIAS | E36: 46725753464 | F36: 503913 | G36: 45802403695 | H36: Software | I36: 2932.32 | J36: 2932.32 | K36: 0 | L36: 244.36 | M36: 0 | N36: 0 | O36: 244.36005 | P36: marcela@altoqi.com.br | Q36: Saving | R36: Saving | S36: 45992 | T36: 46023 | U36: 45996 | V36: 46361 | W36: 12 meses | X36: 12 | Y36: Assinatura | Z36: Renovação com Expansão | AA36: Pix | AB36: 1 | AC36: CS - Saving | AD36: Plano Builder Premium | AE36: Builder | AF36: Premium | AG36: =IF(IFERROR(SEARCH("Recorrente",AA36),0)>0,"Recorrente",IF(AB36=1,"À Vista",IF(AB36<=3,"CC 3x",IF(AB36<=12,"CC 12x",IF(AB36>12,"Recorrente",""))))) -> À Vista | AH36: =IF(AND(SUMIF(E:E,E36,I:I)>=400000,Q36="B2G"),"n","")
A37: 2026 | B37: 1 | C37: 2075043 | D37: IGOR GUIMARAES MATIAS | E37: 46725753464 | F37: 503913 | G37: 45802403697 | H37: Software | I37: 2932.32 | J37: 2932.32 | K37: 0 | L37: 244.36 | M37: 0 | N37: 0 | O37: 244.36005 | P37: marcela@altoqi.com.br | Q37: Saving | R37: Saving | S37: 45992 | T37: 46023 | U37: 45996 | V37: 46361 | W37: 12 meses | X37: 12 | Y37: Assinatura | Z37: Renovação com Expansão | AA37: Pix | AB37: 1 | AC37: CS - Saving | AD37: Plano Eberick Premium | AE37: Eberick | AF37: Premium | AG37: =IF(IFERROR(SEARCH("Recorrente",AA37),0)>0,"Recorrente",IF(AB37=1,"À Vista",IF(AB37<=3,"CC 3x",IF(AB37<=12,"CC 12x",IF(AB37>12,"Recorrente",""))))) -> À Vista | AH37: =IF(AND(SUMIF(E:E,E37,I:I)>=400000,Q37="B2G"),"n","")
A38: 2026 | B38: 1 | C38: 2075043 | D38: IGOR GUIMARAES MATIAS | E38: 46725753464 | F38: 503913 | G38: 45802403698 | H38: Software | I38: 2932.32 | J38: 2932.32 | K38: 0 | L38: 244.36 | M38: 0 | N38: 0 | O38: 244.36005 | P38: marcela@altoqi.com.br | Q38: Saving | R38: Saving | S38: 45992 | T38: 46023 | U38: 45996 | V38: 46361 | W38: 12 meses | X38: 12 | Y38: Assinatura | Z38: Renovação com Expansão | AA38: Pix | AB38: 1 | AC38: CS - Saving | AD38: Plano Builder Professional | AE38: Builder | AF38: Professional | AG38: =IF(IFERROR(SEARCH("Recorrente",AA38),0)>0,"Recorrente",IF(AB38=1,"À Vista",IF(AB38<=3,"CC 3x",IF(AB38<=12,"CC 12x",IF(AB38>12,"Recorrente",""))))) -> À Vista | AH38: =IF(AND(SUMIF(E:E,E38,I:I)>=400000,Q38="B2G"),"n","")
A39: 2026 | B39: 1 | C39: 20945228105 | D39: BMV ENGENHARIA LTDA | E39: 46813173130 | F39: 523210 | G39: 46407636880 | H39: Software | I39: 4278.84 | J39: 4278.84 | K39: 0 | L39: 356.57 | M39: 0 | N39: 0 | O39: 356.575 | P39: silvia.estipe@altoqi.com.br | Q39: Saving | R39: Saving | S39: 45995 | T39: 46023 | U39: 45999 | V39: 46364 | W39: 12 meses | X39: 12 | Y39: Assinatura | Z39: Renovação | AA39: Cartão de crédito - Recorrente | AB39: 12 | AC39: CS - Saving | AD39: Plano Builder Premium | AE39: Builder | AF39: Premium | AG39: =IF(IFERROR(SEARCH("Recorrente",AA39),0)>0,"Recorrente",IF(AB39=1,"À Vista",IF(AB39<=3,"CC 3x",IF(AB39<=12,"CC 12x",IF(AB39>12,"Recorrente",""))))) -> Recorrente | AH39: =IF(AND(SUMIF(E:E,E39,I:I)>=400000,Q39="B2G"),"n","")
A40: 2026 | B40: 1 | C40: 42326226253 | D40: ENERGIA CONSULT - ENGENHARIA, CONSULTORIA E GERENCIAMENTO DE PROJETOS LTDA | E40: 47253502621 | F40: 624563 | G40: 45846126405 | H40: Software | I40: 5754 | J40: 5754 | K40: 0 | L40: 479.5 | M40: 0 | N40: 30.5 | O40: 449 | P40: rubia.estipe@altoqi.com.br | Q40: Saving | R40: Saving | S40: 45992 | T40: 46023 | U40: 45995 | V40: 46360 | W40: 12 meses | X40: 12 | Y40: Assinatura | Z40: Renovação | AA40: Cartão de crédito | AB40: 12 | AC40: CS - Saving | AD40: Plano Eberick Premium | AE40: Eberick | AF40: Premium | AG40: =IF(IFERROR(SEARCH("Recorrente",AA40),0)>0,"Recorrente",IF(AB40=1,"À Vista",IF(AB40<=3,"CC 3x",IF(AB40<=12,"CC 12x",IF(AB40>12,"Recorrente",""))))) -> CC 12x | AH40: =IF(AND(SUMIF(E:E,E40,I:I)>=400000,Q40="B2G"),"n","")
...

Sheet Realizado GD
A1: Ano | B1: Mês | C1: Email | D1: Realizado
A2: 2026 | B2: 1 | C2: ana.camargo@altoqi.com.br | D2: 96
A3: 2026 | B3: 1 | C3: anand.figueiredo@altoqi.com.br | D3: 43
A4: 2026 | B4: 1 | C4: arthur.trevisiol@altoqi.com.br | D4: 106
A5: 2026 | B5: 1 | C5: eliane.guinther@altoqi.com.br | D5: 1
A6: 2026 | B6: 1 | C6: elisa.costa@altoqi.com.br | D6: 124
A7: 2026 | B7: 1 | C7: luiz.senna@altoqi.com.br | D7: 61
A8: 2026 | B8: 1 | C8: maria.eduarda@altoqi.com.br | D8: 2
A9: 2026 | B9: 1 | C9: matheus.lima@altoqi.com.br | D9: 113
A10: 2026 | B10: 1 | C10: renata.scheffer@altoqi.com.br | D10: 41
A11: 2026 | B11: 2 | C11: amanda.bernardez@altoqi.com.br | D11: 1
A12: 2026 | B12: 2 | C12: ana.camargo@altoqi.com.br | D12: 95
A13: 2026 | B13: 2 | C13: anand.figueiredo@altoqi.com.br | D13: 46
... A47: 2026 | B47: 5 | C47: vanessa.sousa@altoqi.com.br | D47: 62

Sheet Cargos e OTEs
A1: Ano | B1: Mês | C1: Cargo | D1: OTE
A2: 2026 | B2: 4 | C2: Account Executive Jr | D2: 3661.2
A3: 2026 | B3: 4 | C3: Account Executive Pl | D3: 4593.6
A4: 2026 | B4: 4 | C4: Account Executive Sr | D4: 5402.94
A5: 2026 | B5: 4 | C5: Inside Sales Jr | D5: 3742.2
A6: 2026 | B6: 4 | C6: Inside Sales Pl | D6: 4356
A7: 2026 | B7: 4 | C7: Inside Sales Sr | D7: 5016
A8: 2026 | B8: 4 | C8: Farmer Jr | D8: 3746.2
A9: 2026 | B9: 4 | C9: Farmer Pl | D9: 4677.12
A10: 2026 | B10: 4 | C10: Farmer Sr | D10: 6011.88
A11: 2026 | B11: 4 | C11: Sales Development Representative (SDR) I | D11: 1650
A12: 2026 | B12: 4 | C12: Sales Development Representative (SDR) II | D12: 1980
A13: 2026 | B13: 4 | C13: Inside Sales B2G Jr | D13: 5880
... A18: 2026 | B18: 4 | C18: Key Account Corporate B2G Sr | D18: 10500
A19: 2026 | B19: 4 | C19: Account Executive B2G Jr
A20: 2026 | B20: 4 | C20: Account Executive B2G Pl
A21: 2026 | B21: 4 | C21: Account Executive B2G Sr | D21: 9660
A22: 2026 | B22: 4 | C22: Technical Pre-Sales Engineer | D22: 3960
A23: 2026 | B23: 4 | C23: Customer Success Saver Analyst Jr | D23: 3750
A24: 2026 | B24: 4 | C24: Customer Success Saver Analyst Pl | D24: 5400
A25: 2026 | B25: 4 | C25: Customer Success Saver Analyst Sr | D25: 8100
A26: 2026 | B26: 4 | C26: Customer Success Saver Specialist | D26: 11500
A27: 2026 | B27: 4 | C27: Customer Success Renewals Coordinator | D27: 12000
A28: 2026 | B28: 4 | C28: Sales Manager B2g | D28: 12075
A29: 2026 | B29: 4 | C29: Demand Generation Coordinator | D29: 3360
A30: 2026 | B30: 4 | C30: Sales Coordinator B2B | D30: 6600
A31: 2026 | B31: 4 | C31: Sales Coordinator Fsb | D31: 5122.95
A32: 2026 | B32: 4 | C32: Sales Manager Fsb | D32: 9424.8
... A49: 2026 | B49: 5 | C49: Key Account Corporate B2G Sr | D49: 10500
A50: 2026 | B50: 5 | C50: Account Executive B2G Jr
A51: 2026 | B51: 5 | C51: Account Executive B2G Pl
A52: 2026 | B52: 5 | C52: Account Executive B2G Sr | D52: 9660
A53: 2026 | B53: 5 | C53: Technical Pre-Sales Engineer | D53: 3960
A54: 2026 | B54: 5 | C54: Customer Success Saver Analyst Jr | D54: 3750
A55: 2026 | B55: 5 | C55: Customer Success Saver Analyst Pl | D55: 5400
A56: 2026 | B56: 5 | C56: Customer Success Saver Analyst Sr | D56: 8100
A57: 2026 | B57: 5 | C57: Customer Success Saver Specialist | D57: 11500
A58: 2026 | B58: 5 | C58: Customer Success Renewals Coordinator | D58: 12000
A59: 2026 | B59: 5 | C59: Sales Manager B2g | D59: 12075
A60: 2026 | B60: 5 | C60: Demand Generation Coordinator | D60: 3360
...

Sheet Metas
A1: Ano | B1: Mês | C1: Consultor | D1: Email | E1: Equipe | F1: Cargo | G1: Gestor | H1: Tipo | I1: Meta Cheia | J1: Desconto na Meta | K1: Meta Proporcional | L1: Ponderação | M1: % Proteção | N1: Adicional na Meta
A2: 2026 | B2: 1 | C2: Anderson Ortiz | D2: anderson.ortiz@altoqi.com.br | E2: Ares | F2: Consultor | G2: sonia.zielinski@altoqi.com.br | H2: MRR | I2: 10000 | J2: 0.5 | K2: =I2*IF(J2="",1,1-J2) -> 5000 | L2: 1
A3: 2026 | B3: 1 | C3: Francisco Guilherme Junior | D3: francisco.junior@altoqi.com.br | E3: Ares | F3: Consultor | G3: sonia.zielinski@altoqi.com.br | H3: MRR | I3: 10000 | K3: =I3*IF(J3="",1,1-J3) -> 10000 | L3: 1
A4: 2026 | B4: 1 | C4: Rodrigo da Rosa Lima | D4: rodrigo.lima@altoqi.com.br | E4: Ares | F4: Consultor | G4: sonia.zielinski@altoqi.com.br | H4: MRR | I4: 0 | K4: =I4*IF(J4="",1,1-J4) -> 0 | L4: 1
A5: 2026 | B5: 1 | C5: Denis Melo Silva | D5: denis.silva@altoqi.com.br | E5: B2B Construtora | F5: Consultor | H5: MRR | I5: 7500 | J5: 0.75 | K5: =I5*IF(J5="",1,1-J5) -> 1875 | L5: 1
A6: 2026 | B6: 1 | C6: Eloyse Silveira | D6: eloyse.silveira@altoqi.com.br | E6: B2B Construtora | F6: Consultor | H6: MRR | I6: 7500 | J6: 0.5 | K6: =I6*IF(J6="",1,1-J6) -> 3750 | L6: 1
A7: 2026 | B7: 1 | C7: Henrique Teixeira Silva | D7: henrique.silva@altoqi.com.br | E7: B2B Construtora | F7: Consultor | H7: MRR | I7: 7500 | J7: 0.33 | K7: =I7*IF(J7="",1,1-J7) -> 5025 | L7: 1
A8: 2026 | B8: 1 | C8: Rafael Acencio | D8: rafael.acencio@altoqi.com.br | E8: B2B Construtora | F8: Consultor | H8: MRR | I8: 7500 | J8: 0.0952 | K8: =I8*IF(J8="",1,1-J8) -> 6786 | L8: 1
A9: 2026 | B9: 1 | C9: Fernanda da Silva Fertonani | D9: fernanda.fertonani@altoqi.com.br | E9: B2B Escritório | F9: Consultor | H9: MRR | I9: 8500 | J9: 0.5 | K9: =I9*IF(J9="",1,1-J9) -> 4250 | L9: 1
A10: 2026 | B10: 1 | C10: Paola Oliveira | D10: paola.oliveira@altoqi.com.br | E10: B2B Escritório | F10: Consultor | H10: MRR | I10: 8500 | K10: =I10*IF(J10="",1,1-J10) -> 8500 | L10: 1
A11: 2026 | B11: 1 | C11: Aline Castilho Pureza | D11: aline.pureza@altoqi.com.br | E11: Farmer | F11: Consultor | G11: sonia.zielinski@altoqi.com.br | H11: MRR | I11: 5000 | K11: =I11*IF(J11="",1,1-J11) -> 5000 | L11: 1
A12: 2026 | B12: 1 | C12: Clidiani Costa | D12: clidiani@altoqi.com.br | E12: Farmer | F12: Consultor | G12: sonia.zielinski@altoqi.com.br | H12: MRR | I12: 8325 | K12: =I12*IF(J12="",1,1-J12) -> 8325 | L12: 1
A13: 2026 | B13: 1 | C13: Debora Vieira | D13: debora.vieira@altoqi.com.br | E13: Farmer | F13: Consultor | G13: sonia.zielinski@altoqi.com.br | H13: MRR | I13: 7120 | J13: 0.5 | K13: =I13*IF(J13="",1,1-J13) -> 3560 | L13: 1
A14: 2026 | B14: 1 | C14: Mariana Rachadel | D14: mariana@altoqi.com.br | E14: Farmer | F14: Consultor | G14: sonia.zielinski@altoqi.com.br | H14: MRR | I14: 10300 | K14: =I14*IF(J14="",1,1-J14) -> 10300 | L14: 1
A15: 2026 | B15: 1 | C15: Renata Parizotto | D15: renata.parizotto@altoqi.com.br | E15: Farmer | F15: Consultor | G15: sonia.zielinski@altoqi.com.br | H15: MRR | I15: 8700 | K15: =I15*IF(J15="",1,1-J15) -> 8700 | L15: 1
A16: 2026 | B16: 1 | C16: Thales Mariante De Sá | D16: thales.sa@altoqi.com.br | E16: Farmer | F16: Consultor | G16: sonia.zielinski@altoqi.com.br | H16: MRR | I16: 7120 | K16: =I16*IF(J16="",1,1-J16) -> 7120 | L16: 1
A17: 2026 | B17: 1 | C17: Artur Machado | D17: artur.francisco@altoqi.com.br | E17: FSB | F17: Consultor | G17: sonia.zielinski@altoqi.com.br | H17: MRR | I17: 8600 | K17: =I17*IF(J17="",1,1-J17) -> 8600 | L17: 1
A18: 2026 | B18: 1 | C18: Eliane Guinther | D18: eliane.guinther@altoqi.com.br | E18: FSB | F18: Consultor | G18: sonia.zielinski@altoqi.com.br | H18: MRR | I18: 8600 | K18: =I18*IF(J18="",1,1-J18) -> 8600 | L18: 1
A19: 2026 | B19: 1 | C19: Renata Scheffer | D19: renata.scheffer@altoqi.com.br | E19: FSB | F19: Consultor | G19: sonia.zielinski@altoqi.com.br | H19: MRR | I19: 8600 | J19: 0.36 | K19: =IF(M19>0,SUMIFS(Negócios!L:L,Negócios!A:A,A19,Negócios!B:B,B19,Negócios!P:P,D19),I19*IF(J19="",1,1-J19)) -> 1386.11 | L19: 1 | M19: 1
A20: 2026 | B20: 1 | C20: Susana Alves Becker | D20: susana.becker@altoqi.com.br | E20: FSB | F20: Consultor | G20: sonia.zielinski@altoqi.com.br | H20: MRR | I20: 9300 | K20: =I20*IF(J20="",1,1-J20) -> 9300 | L20: 1
A21: 2026 | B21: 1 | C21: Ana Camargo | D21: ana.camargo@altoqi.com.br | E21: GD | F21: Consultor | G21: andre.cardoso@altoqi.com.br | H21: Opps | I21: 96 | J21: 0.25 | K21: =I21*IF(J21="",1,1-J21) -> 72 | L21: 1
A22: 2026 | B22: 1 | C22: Anand Freitas Figueiredo | D22: anand.figueiredo@altoqi.com.br | E22: GD | F22: Consultor | H22: Opps | I22: 40 | K22: =I22*IF(J22="",1,1-J22) -> 40 | L22: 1
A23: 2026 | B23: 1 | C23: André Cardoso | D23: andre.cardoso@altoqi.com.br | E23: GD | F23: Gestor | H23: Opps | I23: 442 | K23: =I23*IF(J23="",1,1-J23) -> 442 | L23: 1
A24: 2026 | B24: 1 | C24: Arthur Treivisol | D24: arthur.trevisiol@altoqi.com.br | E24: GD | F24: Consultor | G24: andre.cardoso@altoqi.com.br | H24: Opps | I24: 96 | K24: =I24*IF(J24="",1,1-J24) -> 96 | L24: 1
A25: 2026 | B25: 1 | C25: Elisa Nickel Costa | D25: elisa.costa@altoqi.com.br | E25: GD | F25: Consultor | G25: andre.cardoso@altoqi.com.br | H25: Opps | I25: 96 | K25: =I25*IF(J25="",1,1-J25) -> 96 | L25: 1
A26: 2026 | B26: 1 | C26: Luiz Arthur Falcão Senna | D26: luiz.senna@altoqi.com.br | E26: GD | F26: Consultor | G26: andre.cardoso@altoqi.com.br | H26: Opps | I26: 47 | K26: =I26*IF(J26="",1,1-J26) -> 47 | L26: 1
A27: 2026 | B27: 1 | C27: Maria Eduarda Barbosa | D27: maria.eduarda@altoqi.com.br | E27: GD | F27: Consultor | G27: andre.cardoso@altoqi.com.br
A28: 2026 | B28: 1 | C28: Matheus Fiebig | D28: matheus.lima@altoqi.com.br | E28: GD | F28: Consultor | G28: andre.cardoso@altoqi.com.br | H28: Opps | I28: 96 | K28: =I28*IF(J28="",1,1-J28) -> 96 | L28: 1
A29: 2026 | B29: 1 | C29: Renata Scheffer | D29: renata.scheffer@altoqi.com.br | E29: GD | F29: Consultor | G29: andre.cardoso@altoqi.com.br | H29: Opps | I29: 96 | J29: 0.58 | K29: =I29*IF(J29="",1,1-J29) -> 40.32 | L29: 1
A30: 2026 | B30: 1 | C30: Sarai Daniela | D30: daniela.cabrera@altoqi.com.br | E30: GD | F30: Consultor | H30: Opps | K30: =I30*IF(J30="",1,1-J30) -> 0 | L30: 1
A31: 2026 | B31: 1 | C31: Angélica da Silva Steinbach | D31: angelica.steinbach@altoqi.com.br | E31: Governo | F31: Consultor | G31: marcelo.maestro@altoqi.com.br | H31: ARR | I31: 114309 | K31: =I31*IF(J31="",1,1-J31) -> 114309 | L31: 0.4
A32: 2026 | B32: 1 | C32: Angélica da Silva Steinbach | D32: angelica.steinbach@altoqi.com.br | E32: Governo | F32: Consultor | G32: marcelo.maestro@altoqi.com.br | H32: Booking | I32: 228618 | K32: =I32*IF(J32="",1,1-J32) -> 228618 | L32: 0.6
A33: 2026 | B33: 1 | C33: Carla Araujo | D33: carla.araujo@altoqi.com.br | E33: Governo | F33: Consultor | G33: marcelo.maestro@altoqi.com.br | H33: ARR | I33: 83126 | K33: =I33*IF(J33="",1,1-J33) -> 83126 | L33: 0.4
A34: 2026 | B34: 1 | C34: Carla Araujo | D34: carla.araujo@altoqi.com.br | E34: Governo | F34: Consultor | G34: marcelo.maestro@altoqi.com.br | H34: Booking | I34: 166252 | K34: =I34*IF(J34="",1,1-J34) -> 166252 | L34: 0.6
A35: 2026 | B35: 1 | C35: Deize Marla Rudek | D35: deize.rudek@altoqi.com.br | E35: Governo | F35: Consultor | G35: marcelo.maestro@altoqi.com.br | H35: ARR | I35: 92681.25 | K35: =I35*IF(J35="",1,1-J35) -> 92681.25 | L35: 0.4
A36: 2026 | B36: 1 | C36: Deize Marla Rudek | D36: deize.rudek@altoqi.com.br | E36: Governo | F36: Consultor | G36: marcelo.maestro@altoqi.com.br | H36: Booking | I36: 185362.49 | K36: =I36*IF(J36="",1,1-J36) -> 185362.49 | L36: 0.6
A37: 2026 | B37: 1 | C37: Fernanda Cristina Barbosa | D37: fernanda.barbosa@altoqi.com.br | E37: Governo | F37: Consultor | G37: marcelo.maestro@altoqi.com.br | H37: ARR | I37: 92683.7 | K37: =I37*IF(J37="",1,1-J37) -> 92683.7 | L37: 0.4
A38: 2026 | B38: 1 | C38: Fernanda Cristina Barbosa | D38: fernanda.barbosa@altoqi.com.br | E38: Governo | F38: Consultor | G38: marcelo.maestro@altoqi.com.br | H38: Booking | I38: 185367.4 | K38: =I38*IF(J38="",1,1-J38) -> 185367.4 | L38: 0.6
A39: 2026 | B39: 1 | C39: Henry Carlos Petersen | D39: henry.petersen@altoqi.com.br | E39: Governo | F39: Consultor | G39: marcelo.maestro@altoqi.com.br | H39: ARR | I39: 198811.3 | K39: =I39*IF(J39="",1,1-J39) -> 198811.3 | L39: 0.4
A40: 2026 | B40: 1 | C40: Henry Carlos Petersen | D40: henry.petersen@altoqi.com.br | E40: Governo | F40: Consultor | G40: marcelo.maestro@altoqi.com.br | H40: Booking | I40: 397622.6 | K40: =I40*IF(J40="",1,1-J40) -> 397622.6 | L40: 0.6
...

Sheet Parâmetros
A1: Ano | B1: Mês | C1: Consultor | D1: Email | E1: Equipe | F1: Cargo | G1: Cliff OTE 01 | H1: OTE 01 Cheio | I1: OTE 01 Proporcional | J1: Cliff OTE 02 | K1: OTE 02 Cheio | L1: OTE 02 Proporcional | M1: Cliff OTE 03 | N1: OTE 03 Cheio | O1: OTE 03 Proporcional | P1: Cliff Acelerador 01 | Q1: Acelerador OTE 01 | R1: Cliff Acelerador 02 | S1: Val Acelerador OTE 02 | T1: Cliff Acelerador 03 | U1: Acelerador OTE 03 | V1: Cliff Booking Extra | W1: % Booking Extra
A2: 2026 | B2: 1 | C2: Anderson Ortiz | D2: anderson.ortiz@altoqi.com.br | E2: Ares | F2: Consultor | G2: 0.55 | H2: 3960 | I2: =IF(_xlfn.MAXIFS(Metas!J:J,Metas!A:A,A2,Metas!B:B,B2,Metas!D:D,D2) = 0,H2,H2 * (1-_xlfn.MAXIFS(Metas!J:J,Metas!A:A,A2,Metas!B:B,B2,Metas!D:D,D2))) -> 1980 | L2: =IF(_xlfn.MAXIFS(Metas!J:J,Metas!A:A,A2,Metas!B:B,B2,Metas!D:D,D2) = 0,K2,K2 * (1-_xlfn.MAXIFS(Metas!J:J,Metas!A:A,A2,Metas!B:B,B2,Metas!D:D,D2))) -> 0 | O2: =IF(_xlfn.MAXIFS(Metas!J:J,Metas!A:A,A2,Metas!B:B,B2,Metas!D:D,D2) = 0,N2,N2 * (1-_xlfn.MAXIFS(Metas!J:J,Metas!A:A,A2,Metas!B:B,B2,Metas!D:D,D2))) -> 0 | P2: 0.95 | Q2: 1.15 | R2: 1.05 | S2: 1.25 | V2: =G2 -> 0.55 | W2: 0.02
A3: 2026 | B3: 1 | C3: Francisco Guilherme Junior | D3: francisco.junior@altoqi.com.br | E3: Ares | F3: Consultor | G3: 0.55 | H3: 4176 | I3: =IF(_xlfn.MAXIFS(Metas!J:J,Metas!A:A,A3,Metas!B:B,B3,Metas!D:D,D3) = 0,H3,H3 * (1-_xlfn.MAXIFS(Metas!J:J,Metas!A:A,A3,Metas!B:B,B3,Metas!D:D,D3))) -> 4176 | L3: =IF(_xlfn.MAXIFS(Metas!J:J,Metas!A:A,A3,Metas!B:B,B3,Metas!D:D,D3) = 0,K3,K3 * (1-_xlfn.MAXIFS(Metas!J:J,Metas!A:A,A3,Metas!B:B,B3,Metas!D:D,D3))) -> 0 | O3: =IF(_xlfn.MAXIFS(Metas!J:J,Metas!A:A,A3,Metas!B:B,B3,Metas!D:D,D3) = 0,N3,N3 * (1-_xlfn.MAXIFS(Metas!J:J,Metas!A:A,A3,Metas!B:B,B3,Metas!D:D,D3))) -> 0 | P3: 0.95 | Q3: 1.15 | R3: 1.05 | S3: 1.25 | V3: =G3 -> 0.55 | W3: 0.02
A4: 2026 | B4: 1 | C4: Rodrigo da Rosa Lima | D4: rodrigo.lima@altoqi.com.br | E4: Ares | F4: Consultor | G4: 0.55 | H4: 3564 | I4: =IF(_xlfn.MAXIFS(Metas!J:J,Metas!A:A,A4,Metas!B:B,B4,Metas!D:D,D4) = 0,H4,H4 * (1-_xlfn.MAXIFS(Metas!J:J,Metas!A:A,A4,Metas!B:B,B4,Metas!D:D,D4))) -> 3564 | L4: =IF(_xlfn.MAXIFS(Metas!J:J,Metas!A:A,A4,Metas!B:B,B4,Metas!D:D,D4) = 0,K4,K4 * (1-_xlfn.MAXIFS(Metas!J:J,Metas!A:A,A4,Metas!B:B,B4,Metas!D:D,D4))) -> 0 | O4: =IF(_xlfn.MAXIFS(Metas!J:J,Metas!A:A,A4,Metas!B:B,B4,Metas!D:D,D4) = 0,N4,N4 * (1-_xlfn.MAXIFS(Metas!J:J,Metas!A:A,A4,Metas!B:B,B4,Metas!D:D,D4))) -> 0 | P4: 0.95 | Q4: 1.15 | R4: 1.05 | S4: 1.25 | V4: =G4 -> 0.55 | W4: 0.02
A5: 2026 | B5: 1 | C5: Denis Melo Silva | D5: denis.silva@altoqi.com.br | E5: B2B Construtora | F5: Consultor | G5: 0.55 | H5: 4176 | I5: =IF(_xlfn.MAXIFS(Metas!J:J,Metas!A:A,A5,Metas!B:B,B5,Metas!D:D,D5) = 0,H5,H5 * (1-_xlfn.MAXIFS(Metas!J:J,Metas!A:A,A5,Metas!B:B,B5,Metas!D:D,D5))) -> 1044 | L5: =IF(_xlfn.MAXIFS(Metas!J:J,Metas!A:A,A5,Metas!B:B,B5,Metas!D:D,D5) = 0,K5,K5 * (1-_xlfn.MAXIFS(Metas!J:J,Metas!A:A,A5,Metas!B:B,B5,Metas!D:D,D5))) -> 0 | O5: =IF(_xlfn.MAXIFS(Metas!J:J,Metas!A:A,A5,Metas!B:B,B5,Metas!D:D,D5) = 0,N5,N5 * (1-_xlfn.MAXIFS(Metas!J:J,Metas!A:A,A5,Metas!B:B,B5,Metas!D:D,D5))) -> 0 | P5: 0.95 | Q5: 1.15 | R5: 1.05 | S5: 1.25 | V5: =G5 -> 0.55 | W5: 0.02
A6: 2026 | B6: 1 | C6: Eloyse Silveira | D6: eloyse.silveira@altoqi.com.br | E6: B2B Construtora | F6: Consultor | G6: 0.55 | H6: 4176 | I6: =IF(_xlfn.MAXIFS(Metas!J:J,Metas!A:A,A6,Metas!B:B,B6,Metas!D:D,D6) = 0,H6,H6 * (1-_xlfn.MAXIFS(Metas!J:J,Metas!A:A,A6,Metas!B:B,B6,Metas!D:D,D6))) -> 2088 | L6: =IF(_xlfn.MAXIFS(Metas!J:J,Metas!A:A,A6,Metas!B:B,B6,Metas!D:D,D6) = 0,K6,K6 * (1-_xlfn.MAXIFS(Metas!J:J,Metas!A:A,A6,Metas!B:B,B6,Metas!D:D,D6))) -> 0 | O6: =IF(_xlfn.MAXIFS(Metas!J:J,Metas!A:A,A6,Metas!B:B,B6,Metas!D:D,D6) = 0,N6,N6 * (1-_xlfn.MAXIFS(Metas!J:J,Metas!A:A,A6,Metas!B:B,B6,Metas!D:D,D6))) -> 0 | P6: 0.95 | Q6: 1.15 | R6: 1.05 | S6: 1.25 | V6: =G6 -> 0.55 | W6: 0.02
A7: 2026 | B7: 1 | C7: Henrique Teixeira Silva | D7: henrique.silva@altoqi.com.br | E7: B2B Construtora | F7: Consultor | G7: 0.55 | H7: 4176 | I7: =IF(_xlfn.MAXIFS(Metas!J:J,Metas!A:A,A7,Metas!B:B,B7,Metas!D:D,D7) = 0,H7,H7 * (1-_xlfn.MAXIFS(Metas!J:J,Metas!A:A,A7,Metas!B:B,B7,Metas!D:D,D7))) -> 2797.92 | L7: =IF(_xlfn.MAXIFS(Metas!J:J,Metas!A:A,A7,Metas!B:B,B7,Metas!D:D,D7) = 0,K7,K7 * (1-_xlfn.MAXIFS(Metas!J:J,Metas!A:A,A7,Metas!B:B,B7,Metas!D:D,D7))) -> 0 | O7: =IF(_xlfn.MAXIFS(Metas!J:J,Metas!A:A,A7,Metas!B:B,B7,Metas!D:D,D7) = 0,N7,N7 * (1-_xlfn.MAXIFS(Metas!J:J,Metas!A:A,A7,Metas!B:B,B7,Metas!D:D,D7))) -> 0 | P7: 0.95 | Q7: 1.15 | R7: 1.05 | S7: 1.25 | V7: =G7 -> 0.55 | W7: 0.02
A8: 2026 | B8: 1 | C8: Rafael Acencio | D8: rafael.acencio@altoqi.com.br | E8: B2B Construtora | F8: Consultor | G8: 0.55 | H8: 4176 | I8: =IF(_xlfn.MAXIFS(Metas!J:J,Metas!A:A,A8,Metas!B:B,B8,Metas!D:D,D8) = 0,H8,H8 * (1-_xlfn.MAXIFS(Metas!J:J,Metas!A:A,A8,Metas!B:B,B8,Metas!D:D,D8))) -> 3778.4448 | L8: =IF(_xlfn.MAXIFS(Metas!J:J,Metas!A:A,A8,Metas!B:B,B8,Metas!D:D,D8) = 0,K8,K8 * (1-_xlfn.MAXIFS(Metas!J:J,Metas!A:A,A8,Metas!B:B,B8,Metas!D:D,D8))) -> 0 | O8: =IF(_xlfn.MAXIFS(Metas!J:J,Metas!A:A,A8,Metas!B:B,B8,Metas!D:D,D8) = 0,N8,N8 * (1-_xlfn.MAXIFS(Metas!J:J,Metas!A:A,A8,Metas!B:B,B8,Metas!D:D,D8))) -> 0 | P8: 0.95 | Q8: 1.15 | R8: 1.05 | S8: 1.25 | V8: =G8 -> 0.55 | W8: 0.02
A9: 2026 | B9: 1 | C9: Fernanda da Silva Fertonani | D9: fernanda.fertonani@altoqi.com.br | E9: B2B Escritório | F9: Consultor | G9: 0.55 | H9: 4176 | I9: =IF(_xlfn.MAXIFS(Metas!J:J,Metas!A:A,A9,Metas!B:B,B9,Metas!D:D,D9) = 0,H9,H9 * (1-_xlfn.MAXIFS(Metas!J:J,Metas!A:A,A9,Metas!B:B,B9,Metas!D:D,D9))) -> 2088 | L9: =IF(_xlfn.MAXIFS(Metas!J:J,Metas!A:A,A9,Metas!B:B,B9,Metas!D:D,D9) = 0,K9,K9 * (1-_xlfn.MAXIFS(Metas!J:J,Metas!A:A,A9,Metas!B:B,B9,Metas!D:D,D9))) -> 0 | O9: =IF(_xlfn.MAXIFS(Metas!J:J,Metas!A:A,A9,Metas!B:B,B9,Metas!D:D,D9) = 0,N9,N9 * (1-_xlfn.MAXIFS(Metas!J:J,Metas!A:A,A9,Metas!B:B,B9,Metas!D:D,D9))) -> 0 | P9: 0.95 | Q9: 1.15 | R9: 1.05 | S9: 1.25 | V9: =G9 -> 0.55 | W9: 0.02
A10: 2026 | B10: 1 | C10: Paola Oliveira | D10: paola.oliveira@altoqi.com.br | E10: B2B Escritório | F10: Consultor | G10: 0.55 | H10: 4176 | I10: =IF(_xlfn.MAXIFS(Metas!J:J,Metas!A:A,A10,Metas!B:B,B10,Metas!D:D,D10) = 0,H10,H10 * (1-_xlfn.MAXIFS(Metas!J:J,Metas!A:A,A10,Metas!B:B,B10,Metas!D:D,D10))) -> 4176 | L10: =IF(_xlfn.MAXIFS(Metas!J:J,Metas!A:A,A10,Metas!B:B,B10,Metas!D:D,D10) = 0,K10,K10 * (1-_xlfn.MAXIFS(Metas!J:J,Metas!A:A,A10,Metas!B:B,B10,Metas!D:D,D10))) -> 0 | O10: =IF(_xlfn.MAXIFS(Metas!J:J,Metas!A:A,A10,Metas!B:B,B10,Metas!D:D,D10) = 0,N10,N10 * (1-_xlfn.MAXIFS(Metas!J:J,Metas!A:A,A10,Metas!B:B,B10,Metas!D:D,D10))) -> 0 | P10: 0.95 | Q10: 1.15 | R10: 1.05 | S10: 1.25 | V10: =G10 -> 0.55 | W10: 0.02
A11: 2026 | B11: 1 | C11: Aline Castilho Pureza | D11: aline.pureza@altoqi.com.br | E11: Farmer | F11: Consultor | G11: 0.55 | H11: 3240 | I11: =IF(_xlfn.MAXIFS(Metas!J:J,Metas!A:A,A11,Metas!B:B,B11,Metas!D:D,D11) = 0,H11,H11 * (1-_xlfn.MAXIFS(Metas!J:J,Metas!A:A,A11,Metas!B:B,B11,Metas!D:D,D11))) -> 3240 | L11: =IF(_xlfn.MAXIFS(Metas!J:J,Metas!A:A,A11,Metas!B:B,B11,Metas!D:D,D11) = 0,K11,K11 * (1-_xlfn.MAXIFS(Metas!J:J,Metas!A:A,A11,Metas!B:B,B11,Metas!D:D,D11))) -> 0 | O11: =IF(_xlfn.MAXIFS(Metas!J:J,Metas!A:A,A11,Metas!B:B,B11,Metas!D:D,D11) = 0,N11,N11 * (1-_xlfn.MAXIFS(Metas!J:J,Metas!A:A,A11,Metas!B:B,B11,Metas!D:D,D11))) -> 0 | P11: 0.95 | Q11: 1.15 | R11: 1.05 | S11: 1.25 | V11: =G11 -> 0.55 | W11: 0.02
A12: 2026 | B12: 1 | C12: Clidiani Costa | D12: clidiani@altoqi.com.br | E12: Farmer | F12: Consultor | G12: 0.55 | H12: 6480 | I12: =IF(_xlfn.MAXIFS(Metas!J:J,Metas!A:A,A12,Metas!B:B,B12,Metas!D:D,D12) = 0,H12,H12 * (1-_xlfn.MAXIFS(Metas!J:J,Metas!A:A,A12,Metas!B:B,B12,Metas!D:D,D12))) -> 6480 | J12: 1 | K12: 8100 | L12: =IF(_xlfn.MAXIFS(Metas!J:J,Metas!A:A,A12,Metas!B:B,B12,Metas!D:D,D12) = 0,K12,K12 * (1-_xlfn.MAXIFS(Metas!J:J,Metas!A:A,A12,Metas!B:B,B12,Metas!D:D,D12))) -> 8100 | O12: =IF(_xlfn.MAXIFS(Metas!J:J,Metas!A:A,A12,Metas!B:B,B12,Metas!D:D,D12) = 0,N12,N12 * (1-_xlfn.MAXIFS(Metas!J:J,Metas!A:A,A12,Metas!B:B,B12,Metas!D:D,D12))) -> 0 | P12: 0.95 | Q12: 1.15 | R12: 1.05 | S12: 1.25 | V12: =G12 -> 0.55 | W12: 0.02
A13: 2026 | B13: 1 | C13: Debora Vieira | D13: debora.vieira@altoqi.com.br | E13: Farmer | F13: Consultor | G13: 0.55 | H13: 3240 | I13: =IF(_xlfn.MAXIFS(Metas!J:J,Metas!A:A,A13,Metas!B:B,B13,Metas!D:D,D13) = 0,H13,H13 * (1-_xlfn.MAXIFS(Metas!J:J,Metas!A:A,A13,Metas!B:B,B13,Metas!D:D,D13))) -> 1620 | L13: =IF(_xlfn.MAXIFS(Metas!J:J,Metas!A:A,A13,Metas!B:B,B13,Metas!D:D,D13) = 0,K13,K13 * (1-_xlfn.MAXIFS(Metas!J:J,Metas!A:A,A13,Metas!B:B,B13,Metas!D:D,D13))) -> 0 | O13: =IF(_xlfn.MAXIFS(Metas!J:J,Metas!A:A,A13,Metas!B:B,B13,Metas!D:D,D13) = 0,N13,N13 * (1-_xlfn.MAXIFS(Metas!J:J,Metas!A:A,A13,Metas!B:B,B13,Metas!D:D,D13))) -> 0 | P13: 0.95 | Q13: 1.15 | R13: 1.05 | S13: 1.25 | V13: =G13 -> 0.55 | W13: 0.02
A14: 2026 | B14: 1 | C14: Mariana Rachadel | D14: mariana@altoqi.com.br | E14: Farmer | F14: Consultor | G14: 0.55 | H14: 9200 | I14: =IF(_xlfn.MAXIFS(Metas!J:J,Metas!A:A,A14,Metas!B:B,B14,Metas!D:D,D14) = 0,H14,H14 * (1-_xlfn.MAXIFS(Metas!J:J,Metas!A:A,A14,Metas!B:B,B14,Metas!D:D,D14))) -> 9200 | J14: 1 | K14: 11500 | L14: =IF(_xlfn.MAXIFS(Metas!J:J,Metas!A:A,A14,Metas!B:B,B14,Metas!D:D,D14) = 0,K14,K14 * (1-_xlfn.MAXIFS(Metas!J:J,Metas!A:A,A14,Metas!B:B,B14,Metas!D:D,D14))) -> 11500 | O14: =IF(_xlfn.MAXIFS(Metas!J:J,Metas!A:A,A14,Metas!B:B,B14,Metas!D:D,D14) = 0,N14,N14 * (1-_xlfn.MAXIFS(Metas!J:J,Metas!A:A,A14,Metas!B:B,B14,Metas!D:D,D14))) -> 0 | P14: 0.95 | Q14: 1.15 | R14: 1.05 | S14: 1.25 | V14: =G14 -> 0.55 | W14: 0.02
A15: 2026 | B15: 1 | C15: Renata Parizotto | D15: renata.parizotto@altoqi.com.br | E15: Farmer | F15: Consultor | G15: 0.55 | H15: 4176 | I15: =IF(_xlfn.MAXIFS(Metas!J:J,Metas!A:A,A15,Metas!B:B,B15,Metas!D:D,D15) = 0,H15,H15 * (1-_xlfn.MAXIFS(Metas!J:J,Metas!A:A,A15,Metas!B:B,B15,Metas!D:D,D15))) -> 4176 | L15: =IF(_xlfn.MAXIFS(Metas!J:J,Metas!A:A,A15,Metas!B:B,B15,Metas!D:D,D15) = 0,K15,K15 * (1-_xlfn.MAXIFS(Metas!J:J,Metas!A:A,A15,Metas!B:B,B15,Metas!D:D,D15))) -> 0 | O15: =IF(_xlfn.MAXIFS(Metas!J:J,Metas!A:A,A15,Metas!B:B,B15,Metas!D:D,D15) = 0,N15,N15 * (1-_xlfn.MAXIFS(Metas!J:J,Metas!A:A,A15,Metas!B:B,B15,Metas!D:D,D15))) -> 0 | P15: 0.95 | Q15: 1.15 | R15: 1.05 | S15: 1.25 | V15: =G15 -> 0.55 | W15: 0.02
A16: 2026 | B16: 1 | C16: Thales Mariante De Sá | D16: thales.sa@altoqi.com.br | E16: Farmer | F16: Consultor | G16: 0.55 | H16: 3240 | I16: =IF(_xlfn.MAXIFS(Metas!J:J,Metas!A:A,A16,Metas!B:B,B16,Metas!D:D,D16) = 0,H16,H16 * (1-_xlfn.MAXIFS(Metas!J:J,Metas!A:A,A16,Metas!B:B,B16,Metas!D:D,D16))) -> 3240 | L16: =IF(_xlfn.MAXIFS(Metas!J:J,Metas!A:A,A16,Metas!B:B,B16,Metas!D:D,D16) = 0,K16,K16 * (1-_xlfn.MAXIFS(Metas!J:J,Metas!A:A,A16,Metas!B:B,B16,Metas!D:D,D16))) -> 0 | O16: =IF(_xlfn.MAXIFS(Metas!J:J,Metas!A:A,A16,Metas!B:B,B16,Metas!D:D,D16) = 0,N16,N16 * (1-_xlfn.MAXIFS(Metas!J:J,Metas!A:A,A16,Metas!B:B,B16,Metas!D:D,D16))) -> 0 | P16: 0.95 | Q16: 1.15 | R16: 1.05 | S16: 1.25 | V16: =G16 -> 0.55 | W16: 0.02
A17: 2026 | B17: 1 | C17: Artur Machado | D17: artur.francisco@altoqi.com.br | E17: FSB | F17: Consultor | G17: 0.6 | H17: 3240 | I17: =IF(_xlfn.MAXIFS(Metas!J:J,Metas!A:A,A17,Metas!B:B,B17,Metas!D:D,D17) = 0,H17,H17 * (1-_xlfn.MAXIFS(Metas!J:J,Metas!A:A,A17,Metas!B:B,B17,Metas!D:D,D17))) -> 3240 | L17: =IF(_xlfn.MAXIFS(Metas!J:J,Metas!A:A,A17,Metas!B:B,B17,Metas!D:D,D17) = 0,K17,K17 * (1-_xlfn.MAXIFS(Metas!J:J,Metas!A:A,A17,Metas!B:B,B17,Metas!D:D,D17))) -> 0 | O17: =IF(_xlfn.MAXIFS(Metas!J:J,Metas!A:A,A17,Metas!B:B,B17,Metas!D:D,D17) = 0,N17,N17 * (1-_xlfn.MAXIFS(Metas!J:J,Metas!A:A,A17,Metas!B:B,B17,Metas!D:D,D17))) -> 0 | P17: 0.95 | Q17: 1.15 | R17: 1.05 | S17: 1.25 | V17: =G17 -> 0.6 | W17: 0.02
A18: 2026 | B18: 1 | C18: Eliane Guinther | D18: eliane.guinther@altoqi.com.br | E18: FSB | F18: Consultor | G18: 0.6 | H18: 3240 | I18: =IF(_xlfn.MAXIFS(Metas!J:J,Metas!A:A,A18,Metas!B:B,B18,Metas!D:D,D18) = 0,H18,H18 * (1-_xlfn.MAXIFS(Metas!J:J,Metas!A:A,A18,Metas!B:B,B18,Metas!D:D,D18))) -> 3240 | L18: =IF(_xlfn.MAXIFS(Metas!J:J,Metas!A:A,A18,Metas!B:B,B18,Metas!D:D,D18) = 0,K18,K18 * (1-_xlfn.MAXIFS(Metas!J:J,Metas!A:A,A18,Metas!B:B,B18,Metas!D:D,D18))) -> 0 | O18: =IF(_xlfn.MAXIFS(Metas!J:J,Metas!A:A,A18,Metas!B:B,B18,Metas!D:D,D18) = 0,N18,N18 * (1-_xlfn.MAXIFS(Metas!J:J,Metas!A:A,A18,Metas!B:B,B18,Metas!D:D,D18))) -> 0 | P18: 0.95 | Q18: 1.15 | R18: 1.05 | S18: 1.25 | V18: =G18 -> 0.6 | W18: 0.02
A19: 2026 | B19: 1 | C19: Renata Scheffer | D19: renata.scheffer@altoqi.com.br | E19: FSB | F19: Consultor | G19: 0.6 | H19: 3240 | I19: =IF(_xlfn.MAXIFS(Metas!J:J,Metas!A:A,A19,Metas!B:B,B19,Metas!D:D,D19,Metas!E:E,E19) = 0,H19,H19 * (1-_xlfn.MAXIFS(Metas!J:J,Metas!A:A,A19,Metas!B:B,B19,Metas!D:D,D19,Metas!E:E,E19))) -> 2073.6 | L19: =IF(_xlfn.MAXIFS(Metas!J:J,Metas!A:A,A19,Metas!B:B,B19,Metas!D:D,D19) = 0,K19,K19 * (1-_xlfn.MAXIFS(Metas!J:J,Metas!A:A,A19,Metas!B:B,B19,Metas!D:D,D19))) -> 0 | O19: =IF(_xlfn.MAXIFS(Metas!J:J,Metas!A:A,A19,Metas!B:B,B19,Metas!D:D,D19) = 0,N19,N19 * (1-_xlfn.MAXIFS(Metas!J:J,Metas!A:A,A19,Metas!B:B,B19,Metas!D:D,D19))) -> 0 | P19: 0.95 | Q19: 1.15 | R19: 1.05 | S19: 1.25 | V19: =G19 -> 0.6 | W19: 0.02
A20: 2026 | B20: 1 | C20: Susana Alves Becker | D20: susana.becker@altoqi.com.br | E20: FSB | F20: Consultor | G20: 0.6 | H20: 3960 | I20: =IF(_xlfn.MAXIFS(Metas!J:J,Metas!A:A,A20,Metas!B:B,B20,Metas!D:D,D20) = 0,H20,H20 * (1-_xlfn.MAXIFS(Metas!J:J,Metas!A:A,A20,Metas!B:B,B20,Metas!D:D,D20))) -> 3960 | L20: =IF(_xlfn.MAXIFS(Metas!J:J,Metas!A:A,A20,Metas!B:B,B20,Metas!D:D,D20) = 0,K20,K20 * (1-_xlfn.MAXIFS(Metas!J:J,Metas!A:A,A20,Metas!B:B,B20,Metas!D:D,D20))) -> 0 | O20: =IF(_xlfn.MAXIFS(Metas!J:J,Metas!A:A,A20,Metas!B:B,B20,Metas!D:D,D20) = 0,N20,N20 * (1-_xlfn.MAXIFS(Metas!J:J,Metas!A:A,A20,Metas!B:B,B20,Metas!D:D,D20))) -> 0 | P20: 0.95 | Q20: 1.15 | R20: 1.05 | S20: 1.25 | V20: =G20 -> 0.6 | W20: 0.02
A21: 2026 | B21: 1 | C21: Ana Camargo | D21: ana.camargo@altoqi.com.br | E21: GD | F21: Consultor | G21: 0.7 | H21: 1500 | I21: =IF(_xlfn.MAXIFS(Metas!J:J,Metas!A:A,A21,Metas!B:B,B21,Metas!D:D,D21) = 0,H21,H21 * (1-_xlfn.MAXIFS(Metas!J:J,Metas!A:A,A21,Metas!B:B,B21,Metas!D:D,D21))) -> 1125 | L21: =IF(_xlfn.MAXIFS(Metas!J:J,Metas!A:A,A21,Metas!B:B,B21,Metas!D:D,D21) = 0,K21,K21 * (1-_xlfn.MAXIFS(Metas!J:J,Metas!A:A,A21,Metas!B:B,B21,Metas!D:D,D21))) -> 0 | O21: =IF(_xlfn.MAXIFS(Metas!J:J,Metas!A:A,A21,Metas!B:B,B21,Metas!D:D,D21) = 0,N21,N21 * (1-_xlfn.MAXIFS(Metas!J:J,Metas!A:A,A21,Metas!B:B,B21,Metas!D:D,D21))) -> 0 | P21: 0.9 | Q21: 1.15 | R21: 1 | S21: 1.25
A22: 2026 | B22: 1 | C22: Anand Freitas Figueiredo | D22: anand.figueiredo@altoqi.com.br | E22: GD | F22: Consultor | G22: 0.5 | H22: 1800 | I22: =IF(_xlfn.MAXIFS(Metas!J:J,Metas!A:A,A22,Metas!B:B,B22,Metas!D:D,D22) = 0,H22,H22 * (1-_xlfn.MAXIFS(Metas!J:J,Metas!A:A,A22,Metas!B:B,B22,Metas!D:D,D22))) -> 1800 | L22: =IF(_xlfn.MAXIFS(Metas!J:J,Metas!A:A,A22,Metas!B:B,B22,Metas!D:D,D22) = 0,K22,K22 * (1-_xlfn.MAXIFS(Metas!J:J,Metas!A:A,A22,Metas!B:B,B22,Metas!D:D,D22))) -> 0 | O22: =IF(_xlfn.MAXIFS(Metas!J:J,Metas!A:A,A22,Metas!B:B,B22,Metas!D:D,D22) = 0,N22,N22 * (1-_xlfn.MAXIFS(Metas!J:J,Metas!A:A,A22,Metas!B:B,B22,Metas!D:D,D22))) -> 0 | P22: 0.75 | Q22: 1.15 | R22: 0.9 | S22: 1.25
A23: 2026 | B23: 1 | C23: André Cardoso | D23: andre.cardoso@altoqi.com.br | E23: GD | F23: Gestor | G23: 0.7 | H23: 3200 | I23: =IF(_xlfn.MAXIFS(Metas!J:J,Metas!A:A,A23,Metas!B:B,B23,Metas!D:D,D23) = 0,H23,H23 * (1-_xlfn.MAXIFS(Metas!J:J,Metas!A:A,A23,Metas!B:B,B23,Metas!D:D,D23))) -> 3200 | L23: =IF(_xlfn.MAXIFS(Metas!J:J,Metas!A:A,A23,Metas!B:B,B23,Metas!D:D,D23) = 0,K23,K23 * (1-_xlfn.MAXIFS(Metas!J:J,Metas!A:A,A23,Metas!B:B,B23,Metas!D:D,D23))) -> 0 | O23: =IF(_xlfn.MAXIFS(Metas!J:J,Metas!A:A,A23,Metas!B:B,B23,Metas!D:D,D23) = 0,N23,N23 * (1-_xlfn.MAXIFS(Metas!J:J,Metas!A:A,A23,Metas!B:B,B23,Metas!D:D,D23))) -> 0 | P23: 0.9 | Q23: 1.15 | R23: 1 | S23: 1.25
A24: 2026 | B24: 1 | C24: Arthur Treivisol | D24: arthur.trevisiol@altoqi.com.br | E24: GD | F24: Consultor | G24: 0.7 | H24: 1500 | I24: =IF(_xlfn.MAXIFS(Metas!J:J,Metas!A:A,A24,Metas!B:B,B24,Metas!D:D,D24) = 0,H24,H24 * (1-_xlfn.MAXIFS(Metas!J:J,Metas!A:A,A24,Metas!B:B,B24,Metas!D:D,D24))) -> 1500 | L24: =IF(_xlfn.MAXIFS(Metas!J:J,Metas!A:A,A24,Metas!B:B,B24,Metas!D:D,D24) = 0,K24,K24 * (1-_xlfn.MAXIFS(Metas!J:J,Metas!A:A,A24,Metas!B:B,B24,Metas!D:D,D24))) -> 0 | O24: =IF(_xlfn.MAXIFS(Metas!J:J,Metas!A:A,A24,Metas!B:B,B24,Metas!D:D,D24) = 0,N24,N24 * (1-_xlfn.MAXIFS(Metas!J:J,Metas!A:A,A24,Metas!B:B,B24,Metas!D:D,D24))) -> 0 | P24: 0.9 | Q24: 1.15 | R24: 1 | S24: 1.25
A25: 2026 | B25: 1 | C25: Elisa Nickel Costa | D25: elisa.costa@altoqi.com.br | E25: GD | F25: Consultor | G25: 0.7 | H25: 1500 | I25: =IF(_xlfn.MAXIFS(Metas!J:J,Metas!A:A,A25,Metas!B:B,B25,Metas!D:D,D25) = 0,H25,H25 * (1-_xlfn.MAXIFS(Metas!J:J,Metas!A:A,A25,Metas!B:B,B25,Metas!D:D,D25))) -> 1500 | L25: =IF(_xlfn.MAXIFS(Metas!J:J,Metas!A:A,A25,Metas!B:B,B25,Metas!D:D,D25) = 0,K25,K25 * (1-_xlfn.MAXIFS(Metas!J:J,Metas!A:A,A25,Metas!B:B,B25,Metas!D:D,D25))) -> 0 | O25: =IF(_xlfn.MAXIFS(Metas!J:J,Metas!A:A,A25,Metas!B:B,B25,Metas!D:D,D25) = 0,N25,N25 * (1-_xlfn.MAXIFS(Metas!J:J,Metas!A:A,A25,Metas!B:B,B25,Metas!D:D,D25))) -> 0 | P25: 0.9 | Q25: 1.15 | R25: 1 | S25: 1.25
A26: 2026 | B26: 1 | C26: Luiz Arthur Falcão Senna | D26: luiz.senna@altoqi.com.br | E26: GD | F26: Consultor | G26: 0.7 | H26: 1800 | I26: =IF(_xlfn.MAXIFS(Metas!J:J,Metas!A:A,A26,Metas!B:B,B26,Metas!D:D,D26) = 0,H26,H26 * (1-_xlfn.MAXIFS(Metas!J:J,Metas!A:A,A26,Metas!B:B,B26,Metas!D:D,D26))) -> 1800 | L26: =IF(_xlfn.MAXIFS(Metas!J:J,Metas!A:A,A26,Metas!B:B,B26,Metas!D:D,D26) = 0,K26,K26 * (1-_xlfn.MAXIFS(Metas!J:J,Metas!A:A,A26,Metas!B:B,B26,Metas!D:D,D26))) -> 0 | O26: =IF(_xlfn.MAXIFS(Metas!J:J,Metas!A:A,A26,Metas!B:B,B26,Metas!D:D,D26) = 0,N26,N26 * (1-_xlfn.MAXIFS(Metas!J:J,Metas!A:A,A26,Metas!B:B,B26,Metas!D:D,D26))) -> 0 | P26: 0.9 | Q26: 1.15 | R26: 1 | S26: 1.25
